<mujoco model="sawyer_lift">
    <include file="./common/sawyer_no_gripper.xml" />
    <default>
    </default>
      <asset>
    <texture file="../textures/light-wood.png" type="2d" name="tex-light-wood"/>
    <texture file="../textures/dark-wood.png" type="2d" name="tex-dark-wood"/>

    <material name="light-wood" reflectance="0.5" texrepeat="15 15" texture="tex-light-wood" texuniform="true"/>
    <material name="dark-wood" reflectance="0.5" texrepeat="5 5" texture="tex-dark-wood" texuniform="true"/>
    <!-- plaster walls -->
    <texture file="../textures/cream-plaster.png" type="2d" name="tex-cream-plaster"/>
    <material name="walls_mat" reflectance="0.0" shininess="0.1" specular="0.1" texrepeat="3 3" texture="tex-cream-plaster" texuniform="true"/>

    <!-- <texture builtin="gradient" height="256" rgb1=".9 .9 1." rgb2=".2 .3 .4" type="skybox" width="256"/> -->
    <texture file="../textures/gray-plaster.png" type="2d" name="tex-floor"/>
    <material name="floor_mat" reflectance="0.01" shininess="0.0" specular="0.0" texrepeat="2 2" texture="tex-floor" texuniform="true"/>

    <!-- assets for cabinet -->
    <mesh file="../objects/meshes/cabinet_1.stl" name="cabinet-mesh" scale="0.05 0.05 0.05"/>
    <texture type="2d" file="../textures/wooden-cabinet.png" name="cabinet-texture"/>
    <material name="cabinet-material" reflectance="0.5" texture="cabinet-texture" texuniform="true"/>

    <!-- assets for bin -->
    <mesh file="../objects/meshes/bin.stl" name="bin-mesh" scale="0.75 0.75 0.85"/>
    <texture type="2d" file="../textures/pink-plaster.png" name="bin-texture"/>
    <material name="bin-material" reflectance="0.5" texture="bin-texture" texuniform="true"/>

</asset>
    <visual>
        <headlight ambient=".5 .5 .5" diffuse=".8 .8 .8" specular="0.1 0.1 0.1"/>
        <map znear=".01"/>
        <quality shadowsize="2048"/>
    </visual>

    <worldbody>
        <!-- Walls (visual only) -->
        <geom pos="-2.3 2.5 1.5" quat="0.6532815 0.6532815 0.2705981 0.2705981" size="1.06 1.5 0.01" type="box" conaffinity="0" contype="0" group="1" name="wall_leftcorner_visual" material="walls_mat"/>
        <geom pos="-2.3 -2.5 1.5" quat="0.6532815 0.6532815 -0.2705981 -0.2705981" size="1.06 1.5 0.01" type="box" conaffinity="0" contype="0" group="1" name="wall_rightcorner_visual" material="walls_mat"/>
        <geom pos="1.25 3 1.5" quat="0.7071 0.7071 0 0" size="1.75 1.5 0.01" type="box" conaffinity="0" contype="0" group="1" name="wall_left_visual" material="walls_mat"/>
        <geom pos="1.25 -3 1.5" quat="0.7071 -0.7071 0 0" size="1.75 1.5 0.01" type="box" conaffinity="0" contype="0" group="1" name="wall_right_visual" material="walls_mat"/>
        <geom pos="-0.7 0 1.5" quat="0.5 0.5 0.5 0.5" size="2 2 0.01" type="box" conaffinity="0" contype="0" group="1" name="wall_rear_visual" material="walls_mat"/>
        <geom pos="3 0 1.5" quat="0.5 0.5 -0.5 -0.5" size="3 1.5 0.01" type="box" conaffinity="0" contype="0" group="1" name="wall_front_visual" material="walls_mat"/>

        <!-- Floor -->
        <geom condim="3" material="floor_mat" name="floor" pos="0 0 0.1" size="3 3 .125" type="plane"/>
        
    <body name="cabinet" pos="0.75 1.6 -0.4">
        <geom pos="0 -1.2 1.65" size="1 1 1" type="mesh" mesh="cabinet-mesh" conaffinity="0" contype="0" group="1" name='cabinet' material="cabinet-material" quat="-1.0 0 0 1.0"/>   
    </body>

    <body name="bin" pos="2.3 -0.3 0.3">
        <geom pos="0.3 -0.15 0" size="2 2 2" type="mesh" mesh="bin-mesh" conaffinity="2" contype="2" group="1" name='bin' material="bin-material" quat="1 1 0 0"/>   
    </body>

    <body name="table" pos="1.05 0.0 0.8">
        <geom pos="0 0 0" size="0.4 0.4 0.02" type="box" friction="1 0.005 0.0001"/>
        <geom pos="0 0 0" name="table" material="light-wood" size="0.4 0.4 0.02" type="box" conaffinity="0" contype="0" group="1"/>
        <geom pos="0.38 0.38 -0.4" size="0.02 0.4 0.08" type="cylinder" friction="1 0.005 0.0001" rgba="0 0 1 1" />
        <geom pos="0.38 0.38 -0.4" size="0.02 0.4 0.08" type="cylinder" conaffinity="0" contype="0" group="1" material="light-wood"/>
        <geom pos="-0.38 -0.38 -0.4" size="0.02 0.4 0.08" type="cylinder" friction="1 0.005 0.0001" rgba="0 0 1 1" />
        <geom pos="-0.38 -0.38 -0.4" size="0.02 0.4 0.08" type="cylinder" conaffinity="0" contype="0" group="1" material="light-wood"/>
        <geom pos="-0.38 0.38 -0.4" size="0.02 0.4 0.08" type="cylinder" friction="1 0.005 0.0001" rgba="0 0 1 1" />
        <geom pos="-0.38 0.38 -0.4" size="0.02 0.4 0.08" type="cylinder" conaffinity="0" contype="0" group="1" material="light-wood"/>
        <geom pos="0.38 -0.38 -0.4" size="0.02 0.4 0.08" type="cylinder" friction="1 0.005 0.0001" rgba="0 0 1 1" />
        <geom pos="0.38 -0.38 -0.4" size="0.02 0.4 0.08" type="cylinder" conaffinity="0" contype="0" group="1" material="light-wood"/>
    </body>
    <body name="bin1" pos="0.93 0.0 1.02" quat="0 1 0 1">
        <geom friction="1 0.005 0.0001" pos="0 0.18 0.05" rgba="0 0 1 1" size="0.21 0.01 0.2" type="box" />
        <geom conaffinity="0" contype="0" group="1" name="bin1" material="dark-wood" pos="0 0.18 0.05" size="0.21 0.01 0.20" type="box" />
        <geom friction="1 0.005 0.0001" pos="0 -0.18 0.05" rgba="0 0 1 1" size="0.21 0.01 0.2" type="box" />
        <geom conaffinity="0" contype="0" group="1" material="dark-wood" pos="0 -0.18 0.05" size="0.21 0.01 0.2" type="box" />
        <geom friction="1 0.005 0.0001" pos="0.2 0 0.05" rgba="0 0 1 1" size="0.01 0.18 0.2" type="box" />
        <geom conaffinity="0" contype="0" group="1" material="dark-wood" pos="0.2 0 0.05" size="0.01 0.18 0.2" type="box" />
        <geom friction="1 0.005 0.0001" pos="-0.2 0 0.05" rgba="0 0 1 1" size="0.01 0.18 0.2" type="box" />
        <geom conaffinity="0" contype="0" group="1" material="dark-wood" pos="-0.2 0 0.05" size="0.01 0.18 0.2" type="box" />
    </body>

        <body name="cube" pos="0.92 0.0 0.88">
            <geom contype="1" density="300" conaffinity="1" friction="0.95 0.3 0.1" condim="4" group="1" name="cube" pos="0 0 0" rgba="1 0 0 1" size="0.03 0.03 0.03" type="box"/>
            <site name="cube" pos="0 0 0" rgba="1 0 0 1" size="0.002 0.002 0.002" type="sphere" />
            <joint name="cube" type="free" damping="0.0005"/>
        </body>
        <body name="target" pos="1.04 0.0 0.85">
            <joint armature="0" axis="1 0 0" damping="0" limited="true" name="target_x" pos="0 0 0" range="-.3 .3" stiffness="0" type="slide"/>
            <joint armature="0" axis="0 1 0" damping="0" limited="true" name="target_y" pos="0 0 0" range="-.3 .3" stiffness="0" type="slide"/>
            <geom conaffinity="0" contype="0" group="0" name="target" pos="0 0 0" rgba="0.2 0.8 0.2 1" size=".030 .001 .001" type="cylinder"/>
        </body>
        <!-- DISTRACTOR OBJECTS FOR EVALUATION -->
        <body name="cube_distractor" pos="0.96 0.10 0.88">
            <geom contype="1" density="300" conaffinity="1" friction="0.95 0.3 0.1" condim="4" group="1" name="cube_distractor" pos="0 0 0" rgba="0 0.4 0.8 1" size="0.03 0.03 0.03" type="box"/>
            <site name="cube_distractor" pos="0 0 0" rgba="0 0.4 0.8 1" size="0.002 0.002 0.002" type="sphere" />
            <joint name="cube_distractor" type="free" damping="0.0005"/>
        </body>
        <body name="cube_distractor_q" pos="0.88 -0.08 0.88">
            <geom contype="1" density="300" conaffinity="1" friction="0.95 0.3 0.1" condim="4" group="1" name="cube_distractor_1" pos="0 0 0" rgba="0.76 0.2 0.8 1" size="0.03 0.03 0.03" type="box"/>
            <site name="cube_distractor_1" pos="0 0 0" rgba="0.76 0.2 0.8 1" size="0.002 0.002 0.002" type="sphere" />
            <joint name="cube_distractor_1" type="free" damping="0.0005"/>
        </body>

        
        
    </worldbody>
</mujoco>
